Workbook

Sheet Hướng dẫn
A1: BẢNG TỪ VỰNG, CẤU TRÚC & BỘ THỦ TOCFL (繁體中文)
A2: Đi kèm giáo trình ôn thi TOCFL-CAT 16 tuần (10/2026 – 02/2027). Mục tiêu: B1 → B2 (高階級), định hướng C1.
A4: Cách dùng
A5: 1. Học mỗi ngày 15–20 từ theo 'Lĩnh vực / Chủ đề SGK' trùng với chủ đề của tuần trong giáo trình.
A6: 2. Đọc to ví dụ 3 lần, che cột dịch để tự dịch, rồi đối chiếu. Chép tay chữ 繁體 2 lần để nhớ mặt chữ.
A7: 3. Cột Hán-Việt giúp đoán nghĩa nhanh, nhưng xem kỹ cột 'Phân biệt' — nhiều từ nghĩa khác tiếng Việt (仔細, 便宜, 緊張…).
A8: 4. Thuộc rồi thì chọn 'x' ở cột cuối (ô nền vàng). Bảng tiến độ bên dưới tự cập nhật.
A9: 5. Cấp TBCL là ƯỚC TÍNH để sắp thứ tự ưu tiên (3 ≈ B1, 4 ≈ B2, 5 ≈ C1); tra lại danh sách TBCL chính thức khi cần.
A10: 6. Dùng Filter ở hàng tiêu đề để lọc theo chủ đề hoặc cấp độ.
A12: Bảng tiến độ | B12: Tổng số mục | C12: Đã thuộc | D12: Tỷ lệ
A13: Động từ 動詞 | B13: =COUNTA('Động từ 動詞'!A2:A67) -> 66 | C13: =COUNTIF('Động từ 動詞'!L2:L67,"x") -> 0 | D13: =IF(B13=0,0,C13/B13) -> 0
A14: Tính từ 形容詞 | B14: =COUNTA('Tính từ 形容詞'!A2:A46) -> 45 | C14: =COUNTIF('Tính từ 形容詞'!L2:L46,"x") -> 0 | D14: =IF(B14=0,0,C14/B14) -> 0
A15: Danh từ 名詞 | B15: =COUNTA('Danh từ 名詞'!A2:A53) -> 52 | C15: =COUNTIF('Danh từ 名詞'!L2:L53,"x") -> 0 | D15: =IF(B15=0,0,C15/B15) -> 0
A16: Phó từ 副詞 | B16: =COUNTA('Phó từ 副詞'!A2:A31) -> 30 | C16: =COUNTIF('Phó từ 副詞'!L2:L31,"x") -> 0 | D16: =IF(B16=0,0,C16/B16) -> 0
A17: Liên từ 連接詞 | B17: =COUNTA('Liên từ 連接詞'!A2:A16) -> 15 | C17: =COUNTIF('Liên từ 連接詞'!L2:L16,"x") -> 0 | D17: =IF(B17=0,0,C17/B17) -> 0
A18: Liên kết câu 關聯句型 | B18: =COUNTA('Liên kết câu 關聯句型'!A2:A36) -> 35 | C18: =COUNTIF('Liên kết câu 關聯句型'!K2:K36,"x") -> 0 | D18: =IF(B18=0,0,C18/B18) -> 0
A19: Lượng từ 量詞 | B19: =COUNTA('Lượng từ 量詞'!A2:A26) -> 25 | C19: =COUNTIF('Lượng từ 量詞'!H2:H26,"x") -> 0 | D19: =IF(B19=0,0,C19/B19) -> 0
A20: Bộ thủ 部首 | B20: =COUNTA('Bộ thủ 部首'!A2:A61) -> 60 | C20: =COUNTIF('Bộ thủ 部首'!H2:H61,"x") -> 0 | D20: =IF(B20=0,0,C20/B20) -> 0
A21: Chữ ghép đặc biệt | B21: =COUNTA('Chữ ghép đặc biệt'!A2:A52) -> 51 | C21: =COUNTIF('Chữ ghép đặc biệt'!G2:G52,"x") -> 0 | D21: =IF(B21=0,0,C21/B21) -> 0
A22: TỔNG | B22: =SUM(B13:B21) -> 379 | C22: =SUM(C13:C21) -> 0 | D22: =IF(B22=0,0,C22/B22) -> 0
A24: Ghi chú: ô nền vàng là ô bạn tự điền; số liệu tiến độ là công thức, không cần sửa.

Sheet Động từ 動詞
A1: STT | B1: Từ (繁體) | C1: Pinyin | D1: Hán-Việt | E1: Nghĩa tiếng Việt | F1: Lĩnh vực / Chủ đề SGK | G1: Cách dùng / Cấu trúc | H1: Ví dụ (繁體) | I1: Dịch ví dụ | J1: Phân biệt / Bẫy thường gặp | K1: Cấp TBCL (ước tính) | L1: Đã thuộc (x)
A2: 1 | B2: 影響 | C2: yǐngxiǎng | D2: ảnh hưởng | E2: ảnh hưởng (đến) | F2: Xã hội / Giáo dục | G2: A 影響 B；對 B 有影響；受到…的影響 | H2: 天氣會影響我們的心情。 | I2: Thời tiết ảnh hưởng tâm trạng chúng ta. | J2: Vừa là động từ vừa là danh từ | K2: 4
A3: 2 | B3: 發展 | C3: fāzhǎn | D3: phát triển | E3: phát triển | F3: Kinh tế / Xã hội | G3: 發展經濟；…發展得很快 | H3: 台灣的科技發展得很快。 | I3: Khoa học công nghệ Đài Loan phát triển rất nhanh. | K3: 4
A4: 3 | B4: 解決 | C4: jiějué | D4: giải quyết | E4: giải quyết | F4: Công việc / Đời sống | G4: 解決問題／困難 | H4: 這個問題得趕快解決。 | I4: Vấn đề này phải giải quyết nhanh. | J4: Tân ngữ: 問題, 困難, 矛盾 | K4: 3
A5: 4 | B5: 處理 | C5: chǔlǐ | D5: xử lý | E5: xử lý | F5: Công việc | G5: 處理事情／垃圾／問題 | H5: 這件事我來處理。 | I5: Việc này để tôi xử lý. | K5: 4
A6: 5 | B6: 提供 | C6: tígōng | D6: đề cung | E6: cung cấp | F6: Dịch vụ / Công việc | G6: 提供 + 服務／資料／機會；為…提供… | H6: 學校為學生提供獎學金。 | I6: Trường cấp học bổng cho sinh viên. | J6: Không dùng 提供 + người trực tiếp (提供他 ✗) | K6: 4
A7: 6 | B7: 參加 | C7: cānjiā | D7: tham gia | E7: tham gia | F7: Trường học / Hoạt động | G7: 參加 + 活動／比賽／考試 | H7: 我想參加語言交換活動。 | I7: Tôi muốn tham gia hoạt động trao đổi ngôn ngữ. | J7: 參加 hoạt động/tổ chức; 參與 = tham dự vào quá trình (trang trọng hơn) | K7: 2
A8: 7 | B8: 舉辦 | C8: jǔbàn | D8: cử biện | E8: tổ chức (sự kiện) | F8: Hoạt động / Lễ hội | G8: 舉辦 + 活動／比賽／展覽 | H8: 學校下個月舉辦文化節。 | I8: Tháng sau trường tổ chức lễ hội văn hóa. | J8: Đồng nghĩa: 舉行 (舉行 thiên về sự kiện diễn ra) | K8: 4
A9: 8 | B9: 申請 | C9: shēnqǐng | D9: thân thỉnh | E9: xin, nộp đơn | F9: Trường học / Hành chính | G9: 申請 + 獎學金／簽證／學校 | H9: 我申請了華語文獎學金。 | I9: Tôi đã nộp đơn học bổng Hoa ngữ. | K9: 3
A10: 9 | B10: 預約 | C10: yùyuē | D10: dự ước | E10: đặt hẹn trước | F10: Y tế / Dịch vụ | G10: 預約 + 時間／門診／餐廳 | H10: 看醫生要先上網預約。 | I10: Khám bệnh phải đặt lịch trên mạng trước. | J10: Đồng nghĩa: 訂 (訂位, 訂房) | K10: 4
A11: 10 | B11: 取消 | C11: qǔxiāo | D11: thủ tiêu | E11: hủy bỏ | F11: Du lịch / Hoạt động | G11: 取消 + 活動／訂位／比賽 | H11: 因為颱風，比賽取消了。 | I11: Vì bão, trận đấu bị hủy. | K11: 3
A12: 11 | B12: 延期 | C12: yánqí | D12: diên kỳ | E12: hoãn lại, lùi ngày | F12: Hoạt động | G12: …延期到…；延期舉行 | H12: 考試延期到下星期。 | I12: Kỳ thi hoãn đến tuần sau. | J12: Nội động từ: 活動延期了 | K12: 5
A13: 12 | B13: 通知 | C13: tōngzhī | D13: thông tri | E13: thông báo | F13: Trường học / Công việc | G13: 通知 + 人；收到通知 (n) | H13: 有消息我會通知你。 | I13: Có tin tôi sẽ báo bạn. | J13: Vừa động từ vừa danh từ | K13: 3
A14: 13 | B14: 決定 | C14: juédìng | D14: quyết định | E14: quyết định | F14: Đời sống | G14: 決定 + V；做決定 (n) | H14: 我決定明年去台北念書。 | I14: Tôi quyết định năm sau lên Đài Bắc học. | K14: 2
A15: 14 | B15: 考慮 | C15: kǎolǜ | D15: khảo lự | E15: cân nhắc, suy xét | F15: Đời sống | G15: 考慮 + V/N；考慮一下 | H15: 我再考慮考慮。 | I15: Để tôi cân nhắc thêm. | J15: Lặp lại ABAB: 考慮考慮 | K15: 3
A16: 15 | B16: 選擇 | C16: xuǎnzé | D16: tuyển trạch | E16: lựa chọn | F16: Đời sống / Mua sắm | G16: 選擇 + N；做選擇 | H16: 你可以選擇住宿舍或租房子。 | I16: Bạn có thể chọn ở ký túc xá hoặc thuê nhà. | K16: 3
A17: 16 | B17: 比較 | C17: bǐjiào | D17: tỷ giảo | E17: so sánh; khá, tương đối (phó từ) | F17: Mua sắm | G17: 比較 A 跟 B；比較 + adj (khá…) | H17: 這家的價錢比較便宜。 | I17: Giá tiệm này tương đối rẻ. | J17: Làm phó từ rất phổ biến | K17: 2
A18: 17 | B18: 改善 | C18: gǎishàn | D18: cải thiện | E18: cải thiện | F18: Môi trường / Xã hội | G18: 改善 + 環境／關係／情況 | H18: 政府想改善空氣品質。 | I18: Chính phủ muốn cải thiện chất lượng không khí. | J18: 改善 (tốt hơn) ≠ 改變 (thay đổi, trung tính) | K18: 4
A19: 18 | B19: 改變 | C19: gǎibiàn | D19: cải biến | E19: thay đổi | F19: Xã hội | G19: 改變 + 想法／習慣／計畫 | H19: 出國留學改變了我的想法。 | I19: Du học đã thay đổi suy nghĩ của tôi. | K19: 3
A20: 19 | B20: 增加 | C20: zēngjiā | D20: tăng gia | E20: tăng thêm | F20: Kinh tế | G20: 增加 + 數量；增加了 + số | H20: 觀光客增加了百分之十。 | I20: Du khách tăng 10%. | J20: ≠ 減少 | K20: 3
A21: 20 | B21: 減少 | C21: jiǎnshǎo | D21: giảm thiểu | E21: giảm bớt | F21: Môi trường | G21: 減少 + 垃圾／浪費 | H21: 我們應該減少使用塑膠袋。 | I21: Chúng ta nên giảm dùng túi nhựa. | K21: 3
A22: 21 | B22: 提高 | C22: tígāo | D22: đề cao | E22: nâng cao | F22: Giáo dục / Kinh tế | G22: 提高 + 水準／效率／能力 | H22: 多聽多說能提高口語能力。 | I22: Nghe nói nhiều giúp nâng cao khả năng khẩu ngữ. | J22: Khác 'đề cao' tiếng Việt (tôn vinh) | K22: 4
A23: 22 | B23: 降低 | C23: jiàngdī | D23: giáng đê | E23: hạ thấp, giảm | F23: Kinh tế | G23: 降低 + 價格／成本／溫度 | H23: 公司想降低成本。 | I23: Công ty muốn giảm chi phí. | K23: 4
A24: 23 | B24: 保護 | C24: bǎohù | D24: bảo hộ | E24: bảo vệ | F24: Môi trường | G24: 保護 + 環境／動物／自己 | H24: 大家都應該保護環境。 | I24: Mọi người đều nên bảo vệ môi trường. | J24: Khác 'bảo hộ' tiếng Việt (bảo hộ lao động) | K24: 3
A25: 24 | B25: 浪費 | C25: làngfèi | D25: lãng phí | E25: lãng phí | F25: Môi trường / Đời sống | G25: 浪費 + 時間／錢／食物 | H25: 別浪費食物。 | I25: Đừng lãng phí thức ăn. | K25: 3
A26: 25 | B26: 節省 | C26: jiéshěng | D26: tiết tỉnh | E26: tiết kiệm | F26: Đời sống | G26: 節省 + 時間／錢／能源 | H26: 搭捷運可以節省時間。 | I26: Đi MRT tiết kiệm thời gian. | J26: Đồng nghĩa: 省 (khẩu ngữ) | K26: 4
A27: 26 | B27: 負責 | C27: fùzé | D27: phụ trách | E27: phụ trách, chịu trách nhiệm | F27: Công việc | G27: 負責 + 事情；對…負責 | H27: 他負責這次的活動。 | I27: Anh ấy phụ trách hoạt động lần này. | K27: 4
A28: 27 | B28: 適應 | C28: shìyìng | D28: thích ứng | E28: thích nghi | F28: Du học / Đời sống | G28: 適應 + 環境／生活／天氣 | H28: 我已經適應台灣的生活了。 | I28: Tôi đã quen cuộc sống Đài Loan. | K28: 4
A29: 28 | B29: 習慣 | C29: xíguàn | D29: tập quán | E29: quen; thói quen (n) | F29: Đời sống | G29: 習慣 + N/V；…習慣了；養成習慣 | H29: 我還不習慣吃辣。 | I29: Tôi vẫn chưa quen ăn cay. | J29: Động từ + danh từ | K29: 3
A30: 29 | B30: 尊重 | C30: zūnzhòng | D30: tôn trọng | E30: tôn trọng | F30: Văn hóa / Xã hội | G30: 尊重 + 人／意見／文化 | H30: 我們要尊重不同的文化。 | I30: Ta phải tôn trọng các nền văn hóa khác nhau. | K30: 4
A31: 30 | B31: 支持 | C31: zhīchí | D31: chi trì | E31: ủng hộ | F31: Xã hội | G31: 支持 + 人／意見／決定 | H31: 父母很支持我出國。 | I31: Bố mẹ rất ủng hộ tôi ra nước ngoài. | J31: ≠ 反對 | K31: 4
A32: 31 | B32: 反對 | C32: fǎnduì | D32: phản đối | E32: phản đối | F32: Xã hội | G32: 反對 + N/V | H32: 很多人反對這個政策。 | I32: Nhiều người phản đối chính sách này. | K32: 4
A33: 32 | B33: 拒絕 | C33: jùjué | D33: cự tuyệt | E33: từ chối | F33: Giao tiếp | G33: 拒絕 + 人／邀請／要求 | H33: 他拒絕了我的邀請。 | I33: Anh ấy từ chối lời mời của tôi. | K33: 4
A34: 33 | B34: 接受 | C34: jiēshòu | D34: tiếp thụ | E34: tiếp nhận, chấp nhận | F34: Giao tiếp | G34: 接受 + 意見／邀請／訪問 | H34: 老闆接受了我的建議。 | I34: Sếp chấp nhận đề nghị của tôi. | J34: 接受 (chủ động chấp nhận) ≠ 收到 (nhận được vật) | K34: 4
A35: 34 | B35: 答應 | C35: dāying | D35: đáp ứng | E35: đồng ý, nhận lời | F35: Giao tiếp | G35: 答應 + 人／要求；答應 + V | H35: 他答應幫我搬家。 | I35: Anh ấy nhận lời giúp tôi chuyển nhà. | J35: Khác 'đáp ứng' tiếng Việt | K35: 4
A36: 35 | B36: 建議 | C36: jiànyì | D36: kiến nghị | E36: đề nghị, khuyên | F36: Giao tiếp | G36: 建議 + 人 + V；給…建議 (n) | H36: 醫生建議我多休息。 | I36: Bác sĩ khuyên tôi nghỉ ngơi nhiều. | K36: 3
A37: 36 | B37: 抱怨 | C37: bàoyuàn | D37: bão oán | E37: phàn nàn | F37: Đời sống | G37: 抱怨 + N；向…抱怨 | H37: 他常常抱怨工作太多。 | I37: Anh ấy hay than công việc quá nhiều. | K37: 4
A38: 37 | B38: 表示 | C38: biǎoshì | D38: biểu thị | E38: bày tỏ, cho biết | F38: Tin tức | G38: …表示…(dẫn lời trong tin tức) | H38: 專家表示，今年夏天會很熱。 | I38: Chuyên gia cho biết mùa hè năm nay sẽ rất nóng. | J38: Rất hay gặp trong bài đọc tin tức | K38: 4
A39: 38 | B39: 解釋 | C39: jiěshì | D39: giải thích | E39: giải thích | F39: Trường học | G39: 向…解釋；解釋一下 | H39: 老師解釋了這個語法。 | I39: Thầy giải thích ngữ pháp này. | K39: 3
A40: 39 | B40: 討論 | C40: tǎolùn | D40: thảo luận | E40: thảo luận | F40: Trường học / Công việc | G40: 討論 + 問題；跟…討論 | H40: 我們下課後討論報告。 | I40: Tan học ta thảo luận báo cáo. | K40: 3
...

Sheet Tính từ 形容詞
A1: STT | B1: Từ (繁體) | C1: Pinyin | D1: Hán-Việt | E1: Nghĩa tiếng Việt | F1: Lĩnh vực / Chủ đề SGK | G1: Cách dùng / Cấu trúc | H1: Ví dụ (繁體) | I1: Dịch ví dụ | J1: Phân biệt / Bẫy thường gặp | K1: Cấp TBCL (ước tính) | L1: Đã thuộc (x)
A2: 1 | B2: 方便 | C2: fāngbiàn | D2: phương tiện | E2: tiện lợi | F2: Giao thông / Đời sống | G2: 對…很方便；方便的話 (nếu tiện) | H2: 住在捷運站附近很方便。 | I2: Ở gần ga MRT rất tiện. | J2: ≠ 麻煩 | K2: 2
A3: 2 | B3: 麻煩 | C3: máfan | D3: ma phiền | E3: phiền phức; làm phiền (v) | F3: Giao tiếp | G3: 很麻煩；麻煩你 + V (nhờ lịch sự) | H3: 麻煩你幫我開一下門。 | I3: Phiền bạn mở cửa giúp tôi. | J3: Dùng như động từ nhờ vả rất phổ biến | K3: 2
A4: 3 | B4: 熱鬧 | C4: rènao | D4: nhiệt náo | E4: náo nhiệt | F4: Du lịch | G4: 很熱鬧；熱熱鬧鬧 (lặp AABB) | H4: 夜市晚上很熱鬧。 | I4: Chợ đêm buổi tối rất náo nhiệt. | J4: ≠ 安靜 | K4: 2
A5: 4 | B5: 乾淨 | C5: gānjìng | D5: can tịnh | E5: sạch sẽ | F5: Nhà ở | G5: 乾乾淨淨 (AABB) | H5: 房間打掃得很乾淨。 | I5: Phòng được dọn rất sạch. | J5: Bổ ngữ trình độ: V得很乾淨 | K5: 2
A6: 5 | B6: 舒服 | C6: shūfu | D6: thư phục | E6: dễ chịu, thoải mái | F6: Sức khỏe | G6: 不舒服 = khó chịu, không khỏe | H6: 我今天不太舒服。 | I6: Hôm nay tôi hơi mệt. | K6: 2
A7: 6 | B7: 辛苦 | C7: xīnkǔ | D7: tân khổ | E7: vất vả | F7: Công việc | G7: 辛苦了 (câu cảm ơn) | H7: 你今天辛苦了！ | I7: Hôm nay bạn vất vả rồi! | K7: 3
A8: 7 | B8: 輕鬆 | C8: qīngsōng | D8: khinh tùng | E8: nhẹ nhàng, thoải mái | F8: Công việc | G8: 很輕鬆；輕輕鬆鬆 | H8: 這份工作很輕鬆。 | I8: Công việc này rất nhẹ nhàng. | J8: ≠ 辛苦／緊張 | K8: 3
A9: 8 | B9: 緊張 | C9: jǐnzhāng | D9: khẩn trương | E9: căng thẳng, hồi hộp | F9: Cảm xúc / Thi cử | G9: 對…很緊張；別緊張 | H9: 考試前我總是很緊張。 | I9: Trước kỳ thi tôi luôn hồi hộp. | J9: Khác 'khẩn trương' tiếng Việt (gấp gáp) | K9: 3
A10: 9 | B10: 重要 | C10: zhòngyào | D10: trọng yếu | E10: quan trọng | F10: Chung | G10: 對…很重要 | H10: 健康比錢重要。 | I10: Sức khỏe quan trọng hơn tiền. | K10: 2
A11: 10 | B11: 普遍 | C11: pǔbiàn | D11: phổ biến | E11: phổ biến | F11: Xã hội | G11: 很普遍；普遍 + V (phó từ) | H11: 在台灣騎機車很普遍。 | I11: Ở Đài Loan đi xe máy rất phổ biến. | K11: 4
A12: 11 | B12: 傳統 | C12: chuántǒng | D12: truyền thống | E12: truyền thống | F12: Văn hóa / Lễ hội | G12: 傳統 + 文化／節日；很傳統 | H12: 端午節是傳統節日。 | I12: Tết Đoan Ngọ là lễ truyền thống. | K12: 3
A13: 12 | B13: 豐富 | C13: fēngfù | D13: phong phú | E13: phong phú; làm phong phú (v) | F13: Văn hóa | G13: 內容很豐富；豐富 + 經驗 | H13: 這本書的內容很豐富。 | I13: Nội dung cuốn sách rất phong phú. | K13: 3
A14: 13 | B14: 複雜 | C14: fùzá | D14: phức tạp | E14: phức tạp | F14: Chung | H14: 這個問題很複雜。 | I14: Vấn đề này rất phức tạp. | J14: ≠ 簡單 | K14: 3
A15: 14 | B15: 清楚 | C15: qīngchu | D15: thanh sở | E15: rõ ràng | F15: Trường học | G15: V + 清楚 (bổ ngữ kết quả): 聽清楚、說清楚 | H15: 我沒聽清楚，請再說一次。 | I15: Tôi nghe không rõ, xin nói lại. | J15: Bổ ngữ kết quả rất hay thi | K15: 2
A16: 15 | B16: 詳細 | C16: xiángxì | D16: tường tế | E16: chi tiết | F16: Công việc | G16: 詳細 + 資料；詳細地 + V | H16: 請詳細說明你的計畫。 | I16: Hãy trình bày chi tiết kế hoạch của bạn. | K16: 4
A17: 16 | B17: 嚴重 | C17: yánzhòng | D17: nghiêm trọng | E17: nghiêm trọng | F17: Y tế / Môi trường | G17: 病得很嚴重；嚴重的問題 | H17: 空氣污染越來越嚴重。 | I17: Ô nhiễm không khí ngày càng nghiêm trọng. | K17: 3
A18: 17 | B18: 危險 | C18: wéixiǎn | D18: nguy hiểm | E18: nguy hiểm | F18: Giao thông | G18: 很危險；有危險 (n) | H18: 騎車看手機很危險。 | I18: Vừa chạy xe vừa xem điện thoại rất nguy hiểm. | J18: ≠ 安全 | K18: 3
A19: 18 | B19: 划算 | C19: huásuàn | D19: — | E19: đáng tiền, có lợi | F19: Mua sắm | G19: 很划算；不划算 | H19: 買一送一，很划算。 | I19: Mua một tặng một, rất hời. | J19: Từ khẩu ngữ Đài Loan rất hay gặp | K19: 4
A20: 19 | B20: 適合 | C20: shìhé | D20: thích hợp | E20: phù hợp (động từ, có tân ngữ) | F20: Mua sắm / Công việc | G20: A 適合 B (có tân ngữ) | H20: 這件衣服很適合你。 | I20: Bộ đồ này rất hợp với bạn. | J20: 適合 + tân ngữ; 合適 là tính từ (không tân ngữ) | K20: 3
A21: 20 | B21: 合適 | C21: héshì | D21: hợp thích | E21: phù hợp (tính từ) | F21: Mua sắm | G21: 很合適；對…合適 (KHÔNG có tân ngữ) | H21: 這個價錢很合適。 | I21: Giá này rất hợp lý. | J21: Bẫy kinh điển: 合適你 ✗ → 適合你 ✓ | K21: 3
A22: 21 | B22: 滿意 | C22: mǎnyì | D22: mãn ý | E22: hài lòng | F22: Dịch vụ | G22: 對…很滿意 | H22: 客人對服務很滿意。 | I22: Khách rất hài lòng về dịch vụ. | K22: 3
A23: 22 | B23: 失望 | C23: shīwàng | D23: thất vọng | E23: thất vọng | F23: Cảm xúc | G23: 對…很失望；讓人失望 | H23: 結果讓我很失望。 | I23: Kết quả làm tôi rất thất vọng. | K23: 3
A24: 23 | B24: 感動 | C24: gǎndòng | D24: cảm động | E24: cảm động; làm cảm động (v) | F24: Cảm xúc | G24: 很感動；…讓我很感動 | H24: 這部電影讓我很感動。 | I24: Bộ phim này làm tôi rất cảm động. | K24: 3
A25: 24 | B25: 熱情 | C25: rèqíng | D25: nhiệt tình | E25: nhiệt tình, hiếu khách | F25: Văn hóa / Du lịch | G25: 對人很熱情 | H25: 台灣人對外國人很熱情。 | I25: Người Đài Loan rất nồng hậu với người nước ngoài. | K25: 3
A26: 25 | B26: 親切 | C26: qīnqiè | D26: thân thiết | E26: thân thiện, niềm nở | F26: Dịch vụ | G26: 很親切 | H26: 店員很親切。 | I26: Nhân viên cửa hàng rất niềm nở. | J26: Khác 'thân thiết' tiếng Việt (gần gũi quan hệ) | K26: 4
A27: 26 | B27: 客氣 | C27: kèqi | D27: khách khí | E27: khách sáo, lịch sự | F27: Giao tiếp | G27: 別客氣／不客氣 | H27: 你太客氣了。 | I27: Bạn khách sáo quá. | K27: 2
A28: 27 | B28: 認真 | C28: rènzhēn | D28: nhận chân | E28: chăm chỉ, nghiêm túc | F28: Trường học | G28: 認真 + V；做事很認真 | H28: 他上課很認真。 | I28: Anh ấy học rất chăm chú. | K28: 3
A29: 28 | B29: 仔細 | C29: zǐxì | D29: tử tế | E29: kỹ lưỡng, cẩn thận | F29: Trường học | G29: 仔細 + V；仔仔細細 | H29: 請仔細看題目。 | I29: Hãy đọc kỹ đề bài. | J29: Khác 'tử tế' tiếng Việt (tốt bụng)! | K29: 4
A30: 29 | B30: 粗心 | C30: cūxīn | D30: thô tâm | E30: cẩu thả, bất cẩn | F30: Trường học | G30: 很粗心；粗心大意 | H30: 我太粗心了，寫錯字。 | I30: Tôi bất cẩn quá, viết sai chữ. | J30: ≠ 仔細／小心 | K30: 4
A31: 30 | B31: 積極 | C31: jījí | D31: tích cực | E31: tích cực | F31: Công việc | G31: 積極 + V；很積極 | H31: 她積極參加社團活動。 | I31: Cô ấy tích cực tham gia câu lạc bộ. | J31: ≠ 消極 | K31: 4
A32: 31 | B32: 主動 | C32: zhǔdòng | D32: chủ động | E32: chủ động | F32: Công việc | G32: 主動 + V | H32: 他常主動幫忙。 | I32: Anh ấy thường chủ động giúp. | J32: ≠ 被動 | K32: 4
A33: 32 | B33: 有名 | C33: yǒumíng | D33: hữu danh | E33: nổi tiếng | F33: Du lịch | G33: 很有名；以…有名 (nổi tiếng vì…) | H33: 台南以小吃有名。 | I33: Đài Nam nổi tiếng vì món ăn vặt. | J33: Đồng nghĩa: 著名 (văn viết) | K33: 2
A34: 33 | B34: 無聊 | C34: wúliáo | D34: vô liêu | E34: chán, vô vị | F34: Giải trí | G34: 很無聊 | H34: 這個節目很無聊。 | I34: Chương trình này rất chán. | J34: ≠ 有趣／有意思 | K34: 3
A35: 34 | B35: 奇怪 | C35: qíguài | D35: kỳ quái | E35: lạ, kỳ lạ | F35: Chung | G35: 很奇怪；奇怪的是… | H35: 奇怪，他怎麼還沒來？ | I35: Lạ nhỉ, sao anh ấy chưa đến? | K35: 3
A36: 35 | B36: 一般 | C36: yìbān | D36: nhất ban | E36: bình thường; nói chung | F36: Chung | G36: 一般來說 (nói chung) | H36: 一般來說，台灣的夏天很熱。 | I36: Nói chung mùa hè Đài Loan rất nóng. | K36: 3
A37: 36 | B37: 正常 | C37: zhèngcháng | D37: chính thường | E37: bình thường | F37: Y tế | G37: 很正常；不正常 | H37: 檢查結果一切正常。 | I37: Kết quả kiểm tra đều bình thường. | K37: 3
A38: 37 | B38: 困難 | C38: kùnnán | D38: khốn nan | E38: khó khăn (adj/n) | F38: Đời sống | G38: 遇到困難；很困難 | H38: 有困難可以找老師。 | I38: Có khó khăn có thể tìm thầy cô. | J38: Khác 'khốn nạn'! | K38: 3
A39: 38 | B39: 精彩 | C39: jīngcǎi | D39: tinh thái | E39: đặc sắc, hay | F39: Giải trí | G39: 表演很精彩 | H39: 昨天的表演非常精彩。 | I39: Buổi biểu diễn hôm qua rất đặc sắc. | K39: 4
A40: 39 | B40: 準時 | C40: zhǔnshí | D40: chuẩn thời | E40: đúng giờ | F40: Giao thông / Công việc | G40: 準時 + V；很準時 | H40: 台灣的高鐵很準時。 | I40: Tàu cao tốc Đài Loan rất đúng giờ. | K40: 3
...

Sheet Danh từ 名詞
A1: STT | B1: Từ (繁體) | C1: Pinyin | D1: Hán-Việt | E1: Nghĩa tiếng Việt | F1: Lĩnh vực / Chủ đề SGK | G1: Cách dùng / Cấu trúc | H1: Ví dụ (繁體) | I1: Dịch ví dụ | J1: Phân biệt / Bẫy thường gặp | K1: Cấp TBCL (ước tính) | L1: Đã thuộc (x)
A2: 1 | B2: 經驗 | C2: jīngyàn | D2: kinh nghiệm | E2: kinh nghiệm | F2: Công việc | G2: 有經驗；工作經驗；累積經驗 | H2: 我有兩年的教學經驗。 | I2: Tôi có hai năm kinh nghiệm dạy. | K2: 3
A3: 2 | B3: 機會 | C3: jīhuì | D3: cơ hội | E3: cơ hội | F3: Công việc / Du học | G3: 有機會；把握機會 | H3: 這是一個難得的機會。 | I3: Đây là cơ hội hiếm có. | K3: 2
A4: 3 | B4: 環境 | C4: huánjìng | D4: hoàn cảnh | E4: môi trường | F4: Môi trường / Đời sống | G4: 學習環境；保護環境 | H4: 這裡的學習環境很好。 | I4: Môi trường học ở đây rất tốt. | J4: Khác 'hoàn cảnh' tiếng Việt (tình cảnh) | K4: 3
A5: 4 | B5: 文化 | C5: wénhuà | D5: văn hóa | E5: văn hóa | F5: Văn hóa | G5: 文化差異 (khác biệt văn hóa) | H5: 我對台灣文化很有興趣。 | I5: Tôi rất hứng thú với văn hóa Đài Loan. | K5: 2
A6: 5 | B6: 社會 | C6: shèhuì | D6: xã hội | E6: xã hội | F6: Xã hội | G6: 社會問題；出社會 (ra đời đi làm) | H6: 高齡化是一個社會問題。 | I6: Già hóa dân số là vấn đề xã hội. | K6: 3
A7: 6 | B7: 經濟 | C7: jīngjì | D7: kinh tế | E7: kinh tế | F7: Kinh tế | G7: 經濟發展；經濟不景氣 | H7: 今年經濟不太好。 | I7: Năm nay kinh tế không tốt lắm. | K7: 4
A8: 7 | B8: 政府 | C8: zhèngfǔ | D8: chính phủ | E8: chính phủ | F8: Xã hội / Tin tức | G8: 政府 + 規定／推動 | H8: 政府推動垃圾分類。 | I8: Chính phủ thúc đẩy phân loại rác. | K8: 4
A9: 8 | B9: 科技 | C9: kējì | D9: khoa kỹ | E9: khoa học công nghệ | F9: Khoa học | G9: 科技產品；高科技 | H9: 科技改變了我們的生活。 | I9: Công nghệ thay đổi cuộc sống chúng ta. | K9: 4
A10: 9 | B10: 網路 | C10: wǎnglù | D10: võng lộ | E10: mạng internet | F10: Công nghệ | G10: 上網；網路購物 | H10: 網路上的資料不一定正確。 | I10: Thông tin trên mạng chưa chắc đúng. | J10: Đài Loan: 網路; Đại lục: 網絡 | K10: 3
A11: 10 | B11: 資料 | C11: zīliào | D11: tư liệu | E11: tài liệu, thông tin | F11: Trường học | G11: 查資料；收集資料 | H11: 我在圖書館查資料。 | I11: Tôi tra tài liệu ở thư viện. | K11: 3
A12: 11 | B12: 原因 | C12: yuányīn | D12: nguyên nhân | E12: nguyên nhân | F12: Chung | G12: …的原因是… | H12: 遲到的原因是塞車。 | I12: Lý do đến muộn là kẹt xe. | J12: Câu hỏi đọc hiểu: 為什麼…? | K12: 3
A13: 12 | B13: 結果 | C13: jiéguǒ | D13: kết quả | E13: kết quả; kết cục là (liên từ) | F13: Chung | G13: 結果 + mệnh đề (thường tiêu cực/bất ngờ) | H13: 我沒帶傘，結果淋濕了。 | I13: Tôi không mang ô, kết quả bị ướt. | J13: Làm liên từ = rốt cuộc | K13: 3
A14: 13 | B14: 優點 | C14: yōudiǎn | D14: ưu điểm | E14: ưu điểm | F14: Chung | G14: …的優點是… | H14: 住宿舍的優點是便宜。 | I14: Ưu điểm ở ký túc xá là rẻ. | J14: ≠ 缺點 | K14: 4
A15: 14 | B15: 缺點 | C15: quēdiǎn | D15: khuyết điểm | E15: nhược điểm | F15: Chung | G15: …的缺點是… | H15: 缺點是離市區太遠。 | I15: Nhược điểm là xa trung tâm. | K15: 4
A16: 15 | B16: 能力 | C16: nénglì | D16: năng lực | E16: năng lực | F16: Giáo dục | G16: …的能力；有能力 + V | H16: 他的中文能力很強。 | I16: Năng lực tiếng Trung của anh ấy rất tốt. | K16: 3
A17: 16 | B17: 態度 | C17: tàidù | D17: thái độ | E17: thái độ | F17: Công việc | G17: 態度很好；工作態度 | H17: 服務員的態度很親切。 | I17: Thái độ phục vụ rất niềm nở. | K17: 4
A18: 17 | B18: 壓力 | C18: yālì | D18: áp lực | E18: áp lực | F18: Công việc / Trường học | G18: 壓力很大；有壓力；減輕壓力 | H18: 期末考的壓力很大。 | I18: Áp lực thi cuối kỳ rất lớn. | K18: 3
A19: 18 | B19: 症狀 | C19: zhèngzhuàng | D19: chứng trạng | E19: triệu chứng | F19: Y tế | G19: 有…的症狀 | H19: 感冒的症狀是咳嗽、發燒。 | I19: Triệu chứng cảm là ho, sốt. | K19: 5
A20: 19 | B20: 健保卡 | C20: jiànbǎokǎ | D20: — | E20: thẻ bảo hiểm y tế (Đài Loan) | F20: Y tế | G20: 帶健保卡去看病 | H20: 看病要帶健保卡。 | I20: Đi khám phải mang thẻ bảo hiểm y tế. | J20: Từ riêng của Đài Loan | K20: 4
A21: 20 | B21: 房東 | C21: fángdōng | D21: phòng đông | E21: chủ nhà | F21: Nhà ở | G21: 跟房東簽約 | H21: 房東人很好。 | I21: Chủ nhà rất tốt. | J21: 房客 = người thuê | K21: 3
A22: 21 | B22: 房租 | C22: fángzū | D22: phòng tô | E22: tiền thuê nhà | F22: Nhà ở | G22: 繳房租；房租包水電 | H22: 房租一個月八千塊。 | I22: Tiền thuê 8.000 tệ/tháng. | K22: 3
A23: 22 | B23: 押金 | C23: yājīn | D23: áp kim | E23: tiền đặt cọc | F23: Nhà ở | G23: 付押金；押金兩個月 | H23: 押金是兩個月的房租。 | I23: Tiền cọc là hai tháng tiền nhà. | K23: 5
A24: 23 | B24: 合約 | C24: héyuē | D24: hợp ước | E24: hợp đồng | F24: Nhà ở / Công việc | G24: 簽合約；合約到期 | H24: 合約一年一簽。 | I24: Hợp đồng ký theo năm. | J24: Đài Loan: 合約; Đại lục hay dùng 合同 | K24: 4
A25: 24 | B25: 薪水 | C25: xīnshuǐ | D25: tân thủy | E25: tiền lương | F25: Công việc | G25: 薪水很高；領薪水 | H25: 這份工作薪水不錯。 | I25: Công việc này lương khá. | K25: 3
A26: 25 | B26: 面試 | C26: miànshì | D26: diện thí | E26: phỏng vấn | F26: Công việc | G26: 參加面試；面試官 | H26: 我明天有一個面試。 | I26: Mai tôi có buổi phỏng vấn. | K26: 4
A27: 26 | B27: 同事 | C27: tóngshì | D27: đồng sự | E27: đồng nghiệp | F27: Công việc | H27: 我的同事都很好相處。 | I27: Đồng nghiệp tôi đều dễ chơi. | K27: 2
A28: 27 | B28: 會議 | C28: huìyì | D28: hội nghị | E28: cuộc họp | F28: Công việc | G28: 開會；參加會議 | H28: 下午有一個重要的會議。 | I28: Chiều có một cuộc họp quan trọng. | K28: 3
A29: 28 | B29: 報告 | C29: bàogào | D29: báo cáo | E29: báo cáo, tiểu luận | F29: Trường học | G29: 寫報告；做報告 (thuyết trình) | H29: 下星期要交報告。 | I29: Tuần sau phải nộp báo cáo. | J29: 交報告 = nộp báo cáo | K29: 3
A30: 29 | B30: 成績 | C30: chéngjī | D30: thành tích | E30: điểm số, thành tích | F30: Trường học | G30: 成績很好；考試成績 | H30: 他的成績進步了很多。 | I30: Điểm của anh ấy tiến bộ nhiều. | K30: 3
A31: 30 | B31: 學期 | C31: xuéqí | D31: học kỳ | E31: học kỳ | F31: Trường học | G31: 這學期；上／下學期 | H31: 這學期我修了五門課。 | I31: Kỳ này tôi học năm môn. | K31: 2
A32: 31 | B32: 獎學金 | C32: jiǎngxuéjīn | D32: tưởng học kim | E32: học bổng | F32: Trường học | G32: 申請／拿到獎學金 | H32: 她拿到了全額獎學金。 | I32: Cô ấy nhận học bổng toàn phần. | K32: 4
A33: 32 | B33: 宿舍 | C33: sùshè | D33: túc xá | E33: ký túc xá | F33: Trường học | G33: 住宿舍；宿舍規定 | H33: 宿舍晚上十二點關門。 | I33: KTX đóng cửa lúc 12 giờ đêm. | K33: 3
A34: 33 | B34: 捷運 | C34: jiéyùn | D34: tiệp vận | E34: tàu điện ngầm (MRT) | F34: Giao thông | G34: 搭捷運；捷運站 | H34: 搭捷運到台北車站只要十分鐘。 | I34: Đi MRT đến ga Đài Bắc chỉ 10 phút. | J34: Từ riêng Đài Loan (Đại lục: 地鐵) | K34: 3
A35: 34 | B35: 高鐵 | C35: gāotiě | D35: cao thiết | E35: tàu cao tốc | F35: Giao thông / Du lịch | G35: 搭高鐵；高鐵票 | H35: 搭高鐵去高雄大概一個半小時。 | I35: Đi tàu cao tốc đến Cao Hùng khoảng 1 tiếng rưỡi. | K35: 3
A36: 35 | B36: 悠遊卡 | C36: yōuyóukǎ | D36: — | E36: thẻ EasyCard | F36: Giao thông | G36: 刷悠遊卡；加值 | H36: 悠遊卡的錢不夠了，要加值。 | I36: Thẻ EasyCard hết tiền, phải nạp. | J36: 加值 = nạp tiền (Đài Loan) | K36: 3
A37: 36 | B37: 行李 | C37: xíngli | D37: hành lý | E37: hành lý | F37: Du lịch | G37: 一件行李；托運行李 | H37: 我的行李超重了。 | I37: Hành lý của tôi quá cân. | K37: 3
A38: 37 | B38: 景點 | C38: jǐngdiǎn | D38: cảnh điểm | E38: điểm tham quan | F38: Du lịch | G38: 觀光景點；熱門景點 | H38: 九份是很熱門的景點。 | I38: Cửu Phần là điểm tham quan rất hot. | K38: 3
A39: 38 | B39: 夜市 | C39: yèshì | D39: dạ thị | E39: chợ đêm | F39: Du lịch / Ẩm thực | G39: 逛夜市 | H39: 週末我們去逛夜市吧。 | I39: Cuối tuần mình đi dạo chợ đêm nhé. | J39: 逛 = đi dạo, lượn | K39: 2
A40: 39 | B40: 小吃 | C40: xiǎochī | D40: tiểu cật | E40: món ăn vặt | F40: Ẩm thực | G40: 台灣小吃 | H40: 蚵仔煎是有名的台灣小吃。 | I40: Trứng chiên hàu là món vặt Đài Loan nổi tiếng. | K40: 3
...

Sheet Phó từ 副詞
A1: STT | B1: Từ (繁體) | C1: Pinyin | D1: Hán-Việt | E1: Nghĩa tiếng Việt | F1: Lĩnh vực / Chủ đề SGK | G1: Cách dùng / Cấu trúc | H1: Ví dụ (繁體) | I1: Dịch ví dụ | J1: Phân biệt / Bẫy thường gặp | K1: Cấp TBCL (ước tính) | L1: Đã thuộc (x)
A2: 1 | B2: 本來 | C2: běnlái | D2: bản lai | E2: vốn dĩ, lúc đầu | F2: Kể chuyện | G2: 本來…，後來／可是… | H2: 我本來想去，可是下雨了。 | I2: Lúc đầu tôi định đi, nhưng trời mưa. | J2: Báo hiệu kế hoạch thay đổi → câu hỏi 'rốt cuộc có…?' | K2: 3
A3: 2 | B3: 原來 | C3: yuánlái | D3: nguyên lai | E3: hóa ra; ban đầu | F3: Kể chuyện | G3: 原來 + phát hiện sự thật | H3: 原來你也是越南人！ | I3: Hóa ra bạn cũng là người Việt! | J3: 原來 = phát hiện ra; 本來 = lẽ ra | K3: 3
A4: 3 | B4: 居然 | C4: jūrán | D4: cư nhiên | E4: vậy mà, không ngờ | F4: Cảm xúc | G4: 居然 + V (ngoài dự đoán) | H4: 他居然忘了我的生日。 | I4: Vậy mà anh ấy quên sinh nhật tôi. | J4: Đồng nghĩa: 竟然 | K4: 4
A5: 4 | B5: 竟然 | C5: jìngrán | D5: cánh nhiên | E5: không ngờ, lại | F5: Cảm xúc | G5: 竟然 + V | H5: 這麼簡單的題目，我竟然寫錯了。 | I5: Đề dễ vậy mà tôi lại làm sai. | K5: 4
A6: 5 | B6: 果然 | C6: guǒrán | D6: quả nhiên | E6: quả nhiên, đúng như dự đoán | F6: Kể chuyện | G6: 果然 + V | H6: 氣象報告說會下雨，果然下了。 | I6: Dự báo nói sẽ mưa, quả nhiên mưa thật. | J6: ≠ 居然 (ngoài dự đoán) | K6: 4
A7: 6 | B7: 到底 | C7: dàodǐ | D7: đáo để | E7: rốt cuộc (câu hỏi) | F7: Giao tiếp | G7: 到底 + câu hỏi | H7: 你到底去不去？ | I7: Rốt cuộc bạn có đi không? | J7: Chỉ trong câu hỏi hoặc 'cuối cùng' | K7: 4
A8: 7 | B8: 終於 | C8: zhōngyú | D8: chung ư | E8: cuối cùng (sau thời gian chờ) | F8: Kể chuyện | G8: 終於 + V + 了 | H8: 等了半小時，公車終於來了。 | I8: Đợi nửa tiếng, cuối cùng xe buýt cũng đến. | J8: Mang sắc thái 'mong đợi' | K8: 3
A9: 8 | B9: 幾乎 | C9: jīhū | D9: cơ hồ | E9: hầu như, gần như | F9: Chung | G9: 幾乎 + 都／每天 | H9: 我幾乎每天都喝咖啡。 | I9: Tôi gần như ngày nào cũng uống cà phê. | K9: 4
A10: 9 | B10: 差一點 | C10: chàyìdiǎn | D10: sai nhất điểm | E10: suýt nữa | F10: Kể chuyện | G10: 差一點 + V (suýt xảy ra) | H10: 我差一點遲到。 | I10: Tôi suýt đến muộn. | J10: 差一點遲到 = 差一點沒遲到 (đều là không muộn) | K10: 4
A11: 10 | B11: 恐怕 | C11: kǒngpà | D11: khủng phạ | E11: e rằng | F11: Giao tiếp | G11: 恐怕 + mệnh đề | H11: 恐怕今天來不及了。 | I11: E rằng hôm nay không kịp rồi. | K11: 4
A12: 11 | B12: 畢竟 | C12: bìjìng | D12: tất cánh | E12: dù sao thì, suy cho cùng | F12: Nghị luận | G12: 畢竟 + lý do | H12: 別怪他，他畢竟是新來的。 | I12: Đừng trách anh ấy, dù sao cũng là người mới. | K12: 5
A13: 12 | B13: 其實 | C13: qíshí | D13: kỳ thực | E13: thực ra | F13: Giao tiếp | G13: 其實 + sự thật (trái với tưởng) | H13: 其實中文沒有那麼難。 | I13: Thực ra tiếng Trung không khó đến vậy. | J13: Sau 其實 thường là ý chính → đáp án! | K13: 3
A14: 13 | B14: 反正 | C14: fǎnzhèng | D14: phản chính | E14: đằng nào cũng, dù sao | F14: Giao tiếp | G14: 反正 + lý do | H14: 反正沒事，我陪你去吧。 | I14: Đằng nào cũng rảnh, tôi đi với bạn. | K14: 4
A15: 14 | B15: 尤其 | C15: yóuqí | D15: vưu kỳ | E15: đặc biệt là | F15: Chung | G15: …，尤其是… | H15: 我喜歡水果，尤其是芒果。 | I15: Tôi thích hoa quả, đặc biệt là xoài. | K15: 4
A16: 15 | B16: 簡直 | C16: jiǎnzhí | D16: giản trực | E16: quả thực là, đơn giản là (nhấn mạnh) | F16: Cảm xúc | G16: 簡直 + 太／像… | H16: 今天簡直熱死了。 | I16: Hôm nay quả thực nóng chết đi được. | K16: 5
A17: 16 | B17: 漸漸 | C17: jiànjiàn | D17: tiệm tiệm | E17: dần dần | F17: Kể chuyện | G17: 漸漸地 + V | H17: 天氣漸漸冷了。 | I17: Trời dần lạnh. | J17: Đồng nghĩa: 逐漸 (văn viết) | K17: 4
A18: 17 | B18: 突然 | C18: túrán | D18: đột nhiên | E18: đột nhiên | F18: Kể chuyện | G18: 突然 + V；很突然 (adj) | H18: 突然下起雨來了。 | I18: Đột nhiên mưa rơi. | J18: 突然 làm được tính từ; 忽然 chỉ là phó từ | K18: 3
A19: 18 | B19: 一直 | C19: yìzhí | D19: nhất trực | E19: luôn, liên tục; thẳng | F19: Chung | G19: 一直 + V；一直走 | H19: 他一直在等你。 | I19: Anh ấy vẫn luôn đợi bạn. | K19: 2
A20: 19 | B20: 從來 | C20: cónglái | D20: tùng lai | E20: từ trước đến nay (thường phủ định) | F20: Chung | G20: 從來 + 不／沒 + V | H20: 我從來沒去過日本。 | I20: Tôi chưa từng đi Nhật. | K20: 4
A21: 20 | B21: 曾經 | C21: céngjīng | D21: tằng kinh | E21: đã từng | F21: Kể chuyện | G21: 曾經 + V + 過 | H21: 我曾經在台中住過一年。 | I21: Tôi từng sống ở Đài Trung một năm. | K21: 4
A22: 21 | B22: 剛 | C22: gāng | D22: cương | E22: vừa mới | F22: Thời gian | G22: 剛 + V (thời điểm vừa xảy ra) | H22: 我剛到家。 | I22: Tôi vừa về đến nhà. | J22: 剛 (phó từ) ≠ 剛才 (danh từ thời gian) | K22: 2
A23: 22 | B23: 立刻 | C23: lìkè | D23: lập khắc | E23: lập tức | F23: Thời gian | G23: 立刻 + V | H23: 收到通知後請立刻回覆。 | I23: Nhận thông báo xin trả lời ngay. | J23: Đồng nghĩa: 馬上 (khẩu ngữ) | K23: 3
A24: 23 | B24: 順便 | C24: shùnbiàn | D24: thuận tiện | E24: tiện thể | F24: Giao tiếp | G24: 順便 + V | H24: 你去超商的時候，順便幫我買瓶水。 | I24: Bạn đi cửa hàng tiện lợi thì tiện mua giúp tôi chai nước. | J24: Khác nghĩa 'thuận tiện' tiếng Việt | K24: 4
A25: 24 | B25: 仍然 | C25: réngrán | D25: nhưng nhiên | E25: vẫn, vẫn còn | F25: Nghị luận | G25: 雖然…，仍然… | H25: 雖然很累，他仍然繼續工作。 | I25: Dù rất mệt, anh ấy vẫn tiếp tục làm. | J25: Đồng nghĩa: 還是 / 依然 | K25: 4
A26: 25 | B26: 偏偏 | C26: piānpiān | D26: thiên thiên | E26: cứ lại, lại cứ (trái ý) | F26: Cảm xúc | G26: 偏偏 + V | H26: 我要出門，偏偏下起雨來。 | I26: Tôi định ra ngoài thì trời lại đổ mưa. | K26: 5
A27: 26 | B27: 好像 | C27: hǎoxiàng | D27: hảo tượng | E27: hình như | F27: Chung | G27: 好像 + mệnh đề | H27: 他好像感冒了。 | I27: Hình như anh ấy bị cảm. | J27: Đồng nghĩa: 似乎 (văn viết) | K27: 2
A28: 27 | B28: 難怪 | C28: nánguài | D28: nan quái | E28: thảo nào | F28: Kể chuyện | G28: 難怪 + kết quả (đã biết nguyên nhân) | H28: 他昨天沒睡，難怪這麼累。 | I28: Hôm qua anh ấy không ngủ, thảo nào mệt vậy. | J28: Có nguyên nhân rồi mới dùng 難怪 | K28: 4
A29: 28 | B29: 並 | C29: bìng | D29: tịnh | E29: hoàn toàn (không) — nhấn mạnh phủ định | F29: Nghị luận | G29: 並 + 不／沒 + V (phản bác) | H29: 這件事並不簡單。 | I29: Chuyện này hoàn toàn không đơn giản. | J29: Dùng để bác bỏ ý người khác | K29: 4
A30: 29 | B30: 往往 | C30: wǎngwǎng | D30: vãng vãng | E30: thường thường (quy luật) | F30: Nghị luận | G30: 往往 + V (quy luật, không dùng cho tương lai) | H30: 週末夜市往往人很多。 | I30: Cuối tuần chợ đêm thường rất đông. | J30: 往往 ≠ 常常 (không dùng cho ý định tương lai) | K30: 5
A31: 30 | B31: 千萬 | C31: qiānwàn | D31: thiên vạn | E31: nhất thiết, ngàn vạn lần (dặn dò) | F31: Giao tiếp | G31: 千萬 + 別／不要 + V | H31: 千萬別忘了帶護照。 | I31: Nhất định đừng quên mang hộ chiếu. | K31: 4

Sheet Liên từ 連接詞
A1: STT | B1: Từ (繁體) | C1: Pinyin | D1: Hán-Việt | E1: Nghĩa tiếng Việt | F1: Lĩnh vực / Chủ đề SGK | G1: Cách dùng / Cấu trúc | H1: Ví dụ (繁體) | I1: Dịch ví dụ | J1: Phân biệt / Bẫy thường gặp | K1: Cấp TBCL (ước tính) | L1: Đã thuộc (x)
A2: 1 | B2: 因此 | C2: yīncǐ | D2: nhân thử | E2: vì vậy | F2: Liên kết câu (kết quả) | G2: …，因此… | H2: 他很努力，因此進步得很快。 | I2: Anh ấy rất chăm, vì vậy tiến bộ nhanh. | J2: Văn viết của 所以 | K2: 4
A3: 2 | B3: 於是 | C3: yúshì | D3: ư thị | E3: thế là, bèn | F3: Liên kết câu (trình tự) | G3: …，於是…(hành động tiếp theo) | H3: 天氣很好，於是我們去爬山。 | I3: Trời đẹp, thế là chúng tôi đi leo núi. | J3: Nối hai hành động nối tiếp | K3: 4
A4: 3 | B4: 然而 | C4: rán'ér | D4: nhiên nhi | E4: tuy nhiên | F4: Liên kết câu (đối lập) | G4: …。然而，… | H4: 計畫很好，然而執行很困難。 | I4: Kế hoạch tốt, tuy nhiên thực hiện rất khó. | J4: Văn viết của 但是 | K4: 5
A5: 4 | B5: 可是／但是 | C5: kěshì / dànshì | D5: khả thị / đãn thị | E5: nhưng | F5: Liên kết câu (đối lập) | G5: 雖然…，可是／但是… | H5: 雖然貴，但是很好吃。 | I5: Tuy đắt nhưng rất ngon. | J5: Ý chính thường nằm sau 但是 → đáp án | K5: 1
A6: 5 | B6: 而且 | C6: érqiě | D6: nhi thả | E6: hơn nữa | F6: Liên kết câu (bổ sung) | G6: 不但…，而且… | H6: 這家店便宜，而且很乾淨。 | I6: Tiệm này rẻ, hơn nữa rất sạch. | K6: 2
A7: 6 | B7: 另外 | C7: lìngwài | D7: lánh ngoại | E7: ngoài ra | F7: Liên kết câu (bổ sung) | G7: 另外，… | H7: 另外，請記得帶照片。 | I7: Ngoài ra, nhớ mang ảnh. | K7: 3
A8: 7 | B8: 此外 | C8: cǐwài | D8: thử ngoại | E8: ngoài ra (văn viết) | F8: Liên kết câu (bổ sung) | G8: 此外，… | H8: 此外，學校也提供宿舍。 | I8: Ngoài ra trường cũng có KTX. | K8: 5
A9: 8 | B9: 總之 | C9: zǒngzhī | D9: tổng chi | E9: tóm lại | F9: Liên kết câu (tổng kết) | G9: 總之，…(câu kết luận) | H9: 總之，運動對身體有好處。 | I9: Tóm lại, vận động có lợi cho cơ thể. | J9: Câu sau 總之 = ý chính của đoạn! | K9: 4
A10: 9 | B10: 例如／比如 | C10: lìrú / bǐrú | D10: lệ như / tỷ như | E10: ví dụ như | F10: Liên kết câu (minh họa) | G10: …，例如… | H10: 我喜歡運動，例如游泳、跑步。 | I10: Tôi thích thể thao, ví dụ bơi, chạy. | K10: 3
A11: 10 | B11: 首先…其次…最後 | C11: shǒuxiān… qícì… zuìhòu | D11: thủ tiên… kỳ thứ… tối hậu | E11: trước tiên… tiếp theo… cuối cùng | F11: Liên kết câu (trình tự) | G11: 首先…，其次…，最後… | H11: 首先要報名，其次要繳費，最後等通知。 | I11: Trước tiên đăng ký, tiếp đó nộp phí, cuối cùng chờ thông báo. | J11: Hay dùng cho câu hỏi 'bước nào trước' | K11: 4
A12: 11 | B12: 否則 | C12: fǒuzé | D12: phủ tắc | E12: nếu không thì | F12: Liên kết câu (điều kiện) | G12: …，否則… | H12: 快走吧，否則會遲到。 | I12: Đi nhanh lên, nếu không sẽ muộn. | J12: Đồng nghĩa: 不然 (khẩu ngữ) | K12: 4
A13: 12 | B13: 而 | C13: ér | D13: nhi | E13: mà, còn (đối lập nhẹ) | F13: Liên kết câu (đối lập) | G13: A…，而 B… | H13: 哥哥喜歡運動，而弟弟喜歡看書。 | I13: Anh thích thể thao, còn em thích đọc sách. | K13: 4
A14: 13 | B14: 甚至 | C14: shènzhì | D14: thậm chí | E14: thậm chí | F14: Liên kết (tăng tiến) | G14: …，甚至… | H14: 他很忙，甚至沒時間吃飯。 | I14: Anh ấy bận đến mức thậm chí không có thời gian ăn. | K14: 4
A15: 14 | B15: 以及 | C15: yǐjí | D15: dĩ cập | E15: cùng với, và (văn viết) | F15: Liên kết từ | G15: A、B 以及 C | H15: 請帶護照、照片以及申請表。 | I15: Hãy mang hộ chiếu, ảnh và đơn đăng ký. | K15: 5
A16: 15 | B16: 或者／還是 | C16: huòzhě / háishì | D16: hoặc giả / hoàn thị | E16: hoặc / hay là | F16: Liên kết từ | G16: 還是 dùng trong câu hỏi; 或者 trong câu trần thuật | H16: 你要喝茶還是咖啡？ | I16: Bạn uống trà hay cà phê? | J16: Bẫy kinh điển: câu hỏi lựa chọn → 還是 | K16: 2

Sheet Liên kết câu 關聯句型
A1: STT | B1: Cấu trúc (繁體) | C1: Pinyin | D1: Nghĩa | E1: Quan hệ logic | F1: Cách dùng | G1: Ví dụ (繁體) | H1: Dịch ví dụ | I1: Bẫy / lưu ý | J1: Cấp TBCL (ước tính) | K1: Đã thuộc (x)
A2: 1 | B2: 雖然…，但是／可是… | C2: suīrán…, dànshì… | D2: tuy…nhưng… | E2: Nhượng bộ | F2: Hai vế đối lập | G2: 雖然下雨，但是我們還是去了。 | H2: Tuy mưa nhưng chúng tôi vẫn đi. | I2: Có thể dùng thêm 還是／仍然 ở vế sau | J2: 2
A3: 2 | B3: 不但…，而且／還… | C3: búdàn…, érqiě… | D3: không những… mà còn… | E3: Tăng tiến | F3: Cùng chủ ngữ: chủ ngữ đứng TRƯỚC 不但 | G3: 他不但會說中文，而且會說日文。 | H3: Anh ấy không những nói được tiếng Trung mà còn nói được tiếng Nhật. | I3: Khác chủ ngữ: 不但他會，而且我也會 | J3: 3
A4: 3 | B4: 因為…，所以… | C4: yīnwèi…, suǒyǐ… | D4: vì… nên… | E4: Nhân quả | G4: 因為颱風，所以學校停課。 | H4: Vì bão nên trường nghỉ học. | J4: 1
A5: 4 | B5: 既然…，就… | C5: jìrán…, jiù… | D5: đã… thì… | E5: Nhân quả (suy luận) | F5: Nguyên nhân là sự thật đã biết | G5: 既然你不舒服，就早點回家吧。 | H5: Bạn đã không khỏe thì về sớm đi. | I5: 既然 ≠ 雖然 | J5: 4
A6: 5 | B6: 只要…，就… | C6: zhǐyào…, jiù… | D6: chỉ cần… là… | E6: Điều kiện đủ | G6: 只要努力，就會進步。 | H6: Chỉ cần cố gắng là sẽ tiến bộ. | I6: Đi với 就 | J6: 3
A7: 6 | B7: 只有…，才… | C7: zhǐyǒu…, cái… | D7: chỉ có… mới… | E7: Điều kiện cần (duy nhất) | G7: 只有多練習，才能說得流利。 | H7: Chỉ có luyện nhiều mới nói lưu loát. | I7: 只有 → 才 (không dùng 就) | J7: 4
A8: 7 | B8: 除非…，否則／不然… | C8: chúfēi…, fǒuzé… | D8: trừ phi… nếu không… | E8: Điều kiện | G8: 除非下大雨，否則比賽照常舉行。 | H8: Trừ khi mưa to, nếu không trận đấu diễn ra bình thường. | J8: 5
A9: 8 | B9: 無論／不管…，都… | C9: wúlùn / bùguǎn…, dōu… | D9: bất kể… đều… | E9: Điều kiện vô điều kiện | F9: Sau 無論 phải có từ nghi vấn hoặc A 還是 B | G9: 不管多忙，他都每天運動。 | H9: Dù bận thế nào anh ấy cũng tập mỗi ngày. | I9: Bẫy: 不管很忙 ✗ → 不管多忙 ✓ | J9: 4
A10: 9 | B10: 即使／就算…，也… | C10: jíshǐ / jiùsuàn…, yě… | D10: cho dù… cũng… | E10: Nhượng bộ giả định | G10: 即使下雨，我也要去。 | H10: Cho dù mưa tôi cũng đi. | I10: 即使 (giả định) ≠ 雖然 (sự thật) | J10: 4
A11: 10 | B11: 如果／要是…，就… | C11: rúguǒ / yàoshì…, jiù… | D11: nếu… thì… | E11: Giả định | G11: 如果有問題，就問老師。 | H11: Nếu có vấn đề thì hỏi thầy. | J11: 2
A12: 11 | B12: 要不是…，… | C12: yàobúshì… | D12: nếu không phải (nhờ)… | E12: Giả định trái sự thật | G12: 要不是你幫忙，我一定來不及。 | H12: Nếu không nhờ bạn giúp, tôi chắc chắn không kịp. | J12: 5
A13: 12 | B13: 一…就… | C13: yī… jiù… | D13: hễ… là… / vừa… liền… | E13: Thời gian / Điều kiện | G13: 我一到家就睡覺了。 | H13: Tôi vừa về đến nhà là ngủ luôn. | J13: 3
A14: 13 | B14: 越…越… | C14: yuè… yuè… | D14: càng… càng… | E14: Tăng tiến | G14: 中文越學越有意思。 | H14: Tiếng Trung càng học càng thú vị. | I14: 越來越 + adj = ngày càng | J14: 3
A15: 14 | B15: 連…都／也… | C15: lián… dōu / yě… | D15: ngay cả… cũng… | E15: Nhấn mạnh | G15: 他連一句中文都不會說。 | H15: Anh ấy ngay cả một câu tiếng Trung cũng không nói được. | I15: Luôn cặp với 都／也 | J15: 4
A16: 15 | B16: 一邊…一邊… | C16: yìbiān… yìbiān… | D16: vừa… vừa… (hai hành động) | E16: Đồng thời | F16: Hai động từ hành động | G16: 他一邊吃飯一邊看電視。 | H16: Anh ấy vừa ăn vừa xem TV. | I16: 又…又… dùng cho tính chất (adj) | J16: 2
A17: 16 | B17: 又…又… | C17: yòu… yòu… | D17: vừa… vừa… (tính chất) | E17: Đồng thời | F17: Hai tính từ cùng chiều | G17: 這裡的水果又便宜又好吃。 | H17: Hoa quả ở đây vừa rẻ vừa ngon. | J17: 2
A18: 17 | B18: 既…又／也… | C18: jì… yòu… | D18: vừa… vừa… (văn viết) | E18: Đồng thời | G18: 她既聰明又努力。 | H18: Cô ấy vừa thông minh vừa chăm chỉ. | J18: 4
A19: 18 | B19: 不是…，而是… | C19: búshì…, érshì… | D19: không phải… mà là… | E19: Đính chính | G19: 我不是不想去，而是沒時間。 | H19: Tôi không phải không muốn đi, mà là không có thời gian. | I19: Ý chính ở sau 而是 | J19: 4
A20: 19 | B20: 不是…，就是… | C20: búshì…, jiùshì… | D20: không phải… thì là… | E20: Lựa chọn | G20: 週末他不是看書，就是打球。 | H20: Cuối tuần anh ấy không đọc sách thì chơi bóng. | I20: Khác 不是…而是… | J20: 4
A21: 20 | B21: 與其…，不如… | C21: yǔqí…, bùrú… | D21: thay vì… chi bằng… | E21: Lựa chọn | G21: 與其在家睡覺，不如出去走走。 | H21: Thay vì ở nhà ngủ, chi bằng ra ngoài dạo. | I21: Chọn vế sau 不如 | J21: 5
A22: 21 | B22: 寧可…，也不… | C22: nìngkě…, yě bù… | D22: thà… chứ không… | E22: Lựa chọn | G22: 我寧可走路，也不想搭擠的公車。 | H22: Tôi thà đi bộ còn hơn đi xe buýt chật. | J22: 5
A23: 22 | B23: 先…，再／然後… | C23: xiān…, zài… | D23: trước… rồi… | E23: Trình tự | G23: 先洗手，再吃飯。 | H23: Rửa tay trước rồi ăn. | J23: 2
A24: 23 | B24: 除了…以外，還／也… | C24: chúle… yǐwài, hái… | D24: ngoài… ra, còn… | E24: Bổ sung | F24: 除了…以外，都… = trừ… ra | G24: 除了中文以外，我還學日文。 | H24: Ngoài tiếng Trung, tôi còn học tiếng Nhật. | I24: Có 還/也 = bao gồm; có 都 = loại trừ | J24: 3
A25: 24 | B25: 對…來說 | C25: duì… láishuō | D25: đối với… mà nói | E25: Quan điểm | G25: 對我來說，發音最難。 | H25: Với tôi, phát âm là khó nhất. | J25: 3
A26: 25 | B26: 拿…來說 | C26: ná… láishuō | D26: lấy… làm ví dụ | E26: Minh họa | G26: 拿台北來說，房租很貴。 | H26: Lấy Đài Bắc làm ví dụ, tiền nhà rất đắt. | J26: 5
A27: 26 | B27: 把 + O + V + bổ ngữ | C27: bǎ | D27: (câu chữ 把) | E27: Xử lý tân ngữ | F27: S + 把 + O + V + 了/到/在/給/得…(động từ không đứng một mình) | G27: 請把門關上。 | H27: Hãy đóng cửa lại. | I27: Bẫy: 把書看 ✗ → 把書看完 ✓ | J27: 3
A28: 27 | B28: 被 + (người) + V + bổ ngữ | C28: bèi | D28: (câu bị động) | E28: Bị động | F28: S + 被 + (tác nhân) + V + 了/走/壞… | G28: 我的腳踏車被偷了。 | H28: Xe đạp của tôi bị trộm rồi. | I28: Thường mang nghĩa không may | J28: 3
A29: 28 | B29: 是…的 | C29: shì… de | D29: (nhấn mạnh thời gian/nơi/cách thức) | E29: Nhấn mạnh | F29: Việc ĐÃ xảy ra: nhấn mạnh khi nào, ở đâu, bằng gì | G29: 我是去年來台灣的。 | H29: Tôi đến Đài Loan (là) vào năm ngoái. | J29: 2
A30: 29 | B30: A 比 B + adj + (多了／一點) | C30: bǐ | D30: (so sánh hơn) | E30: So sánh | F30: Không dùng 很/非常 trong câu 比 | G30: 今天比昨天冷多了。 | H30: Hôm nay lạnh hơn hôm qua nhiều. | I30: Bẫy: 比…很冷 ✗ | J30: 2
A31: 30 | B31: A 沒有 B (那麼) + adj | C31: méiyǒu | D31: (so sánh kém) | E31: So sánh | G31: 高雄沒有台北那麼冷。 | H31: Cao Hùng không lạnh bằng Đài Bắc. | J31: 3
A32: 31 | B32: V + 得／不 + bổ ngữ (可能補語) | C32: de / bu | D32: (bổ ngữ khả năng) | E32: Khả năng | F32: 聽得懂／聽不懂；買得到／買不到 | G32: 這麼多菜，我吃不完。 | H32: Nhiều món vậy tôi ăn không hết. | I32: Nghe hiểu hội thoại cần nắm chắc | J32: 3
A33: 32 | B33: V + 起來 | C33: qǐlái | D33: (bắt đầu; xét về mặt…) | E33: Bổ ngữ xu hướng mở rộng | F33: 看起來 (trông có vẻ)；說起來 (nói ra thì) | G33: 這個蛋糕看起來很好吃。 | H33: Bánh này trông có vẻ ngon. | J33: 3
A34: 33 | B34: V + 下去 | C34: xiàqù | D34: (tiếp tục) | E34: Bổ ngữ xu hướng mở rộng | G34: 請繼續說下去。 | H34: Hãy tiếp tục nói đi. | J34: 4
A35: 34 | B35: V + 出來 | C35: chūlái | D35: (nhận ra, làm ra) | E35: Bổ ngữ xu hướng mở rộng | F35: 看出來／想出來／聽出來 | G35: 我聽出來他是南部人。 | H35: Tôi nghe ra anh ấy là người miền Nam. | J35: 4
A36: 35 | B36: …的時候／以後／以前 | C36: de shíhou | D36: khi… / sau khi… / trước khi… | E36: Thời gian | G36: 吃飯以前要洗手。 | H36: Trước khi ăn phải rửa tay. | J36: 2

Sheet Lượng từ 量詞
A1: STT | B1: Lượng từ | C1: Pinyin | D1: Hán-Việt | E1: Nghĩa / dùng cho | F1: Ví dụ (繁體) | G1: Ghi chú | H1: Đã thuộc (x)
A2: 1 | B2: 個 | C2: ge | D2: cá | E2: cái, người (chung) | F2: 一個人、一個問題 | G2: Lượng từ chung, dùng khi không chắc
A3: 2 | B3: 位 | C3: wèi | D3: vị | E3: vị (người, lịch sự) | F3: 一位老師、三位客人 | G3: Lịch sự hơn 個
A4: 3 | B4: 張 | C4: zhāng | D4: trương | E4: tờ, tấm (vật phẳng) | F4: 一張紙、兩張票、一張桌子 | G4: Vật có mặt phẳng
A5: 4 | B5: 本 | C5: běn | D5: bản | E5: quyển | F5: 一本書、一本雜誌
A6: 5 | B6: 件 | C6: jiàn | D6: kiện | E6: chiếc (áo); việc | F6: 一件衣服、一件事
A7: 6 | B7: 條 | C7: tiáo | D7: điều | E7: cái (vật dài); con (cá) | F7: 一條路、一條魚、一條褲子
A8: 7 | B8: 隻 | C8: zhī | D8: chích | E8: con (động vật); chiếc (một trong đôi) | F8: 一隻貓、一隻手 | G8: Đại lục viết 只
A9: 8 | B9: 雙 | C9: shuāng | D9: song | E9: đôi | F9: 一雙鞋、一雙筷子
A10: 9 | B10: 台 | C10: tái | D10: đài | E10: chiếc (máy móc) | F10: 一台電腦、一台冷氣 | G10: Đài Loan hay dùng 台
A11: 10 | B11: 輛 | C11: liàng | D11: lượng | E11: chiếc (xe) | F11: 一輛車、一輛機車
A12: 11 | B12: 家 | C12: jiā | D12: gia | E12: (cửa hàng, công ty) | F12: 一家餐廳、一家公司
A13: 12 | B13: 間 | C13: jiān | D13: gian | E13: gian (phòng) | F13: 一間教室、一間套房
A14: 13 | B14: 杯 | C14: bēi | D14: bôi | E14: cốc, ly | F14: 一杯咖啡
A15: 14 | B15: 碗 | C15: wǎn | D15: oản | E15: bát | F15: 一碗牛肉麵
A16: 15 | B16: 份 | C16: fèn | D16: phần | E16: phần; bản (tài liệu); công việc | F16: 一份工作、一份報紙 | G16: 一份工作 hay thi
A17: 16 | B17: 封 | C17: fēng | D17: phong | E17: bức (thư) | F17: 一封信、一封電子郵件
A18: 17 | B18: 場 | C18: chǎng | D18: trường | E18: trận, buổi (sự kiện) | F18: 一場比賽、一場電影、一場雨
A19: 18 | B19: 次 | C19: cì | D19: thứ | E19: lần | F19: 去過三次 | G19: Lượng từ động tác
A20: 19 | B20: 趟 | C20: tàng | D20: thảng | E20: chuyến (đi lại) | F20: 去一趟銀行 | G20: Lượng từ động tác, có đi có về
A21: 20 | B21: 頓 | C21: dùn | D21: đốn | E21: bữa (ăn); trận (mắng) | F21: 一頓飯
A22: 21 | B22: 門 | C22: mén | D22: môn | E22: môn (học) | F22: 一門課
A23: 22 | B23: 篇 | C23: piān | D23: thiên | E23: bài (văn) | F23: 一篇文章、一篇報告
A24: 23 | B24: 種 | C24: zhǒng | D24: chủng | E24: loại | F24: 三種語言
A25: 24 | B25: 棵 | C25: kē | D25: khỏa | E25: cây | F25: 一棵樹
A26: 25 | B26: 座 | C26: zuò | D26: tọa | E26: (núi, tòa nhà, cầu) | F26: 一座山、一座橋

Sheet Bộ thủ 部首
A1: STT | B1: Bộ thủ | C1: Pinyin | D1: Tên Hán-Việt | E1: Ý nghĩa | F1: Biến thể / vị trí | G1: Chữ thường gặp (繁體) | H1: Đã thuộc (x)
A2: 1 | B2: 人／亻 | C2: rén | D2: Nhân | E2: người | F2: 亻 bên trái | G2: 你、他、們、住、休、信、借
A3: 2 | B3: 口 | C3: kǒu | D3: Khẩu | E3: miệng; lời nói | F3: trái/dưới/bao | G3: 吃、喝、叫、唱、問、告、嗎
A4: 3 | B4: 手／扌 | C4: shǒu | D4: Thủ | E4: tay; động tác tay | F4: 扌 bên trái | G4: 打、拿、找、抱、推、拉、掛
A5: 4 | B5: 心／忄 | C5: xīn | D5: Tâm | E5: tim; cảm xúc, suy nghĩ | F5: 忄 bên trái; 心 bên dưới | G5: 想、忘、念、怕、快、情、慢
A6: 5 | B6: 水／氵 | C6: shuǐ | D6: Thủy | E6: nước; chất lỏng | F6: 氵 bên trái | G6: 河、海、洗、湯、酒、清、法
A7: 6 | B7: 火／灬 | C7: huǒ | D7: Hỏa | E7: lửa; nhiệt | F7: 灬 bên dưới | G7: 炒、燒、熱、煮、烤、燈、照
A8: 7 | B8: 木 | C8: mù | D8: Mộc | E8: cây, gỗ | F8: trái/dưới | G8: 林、森、樹、椅、桌、校、材
A9: 8 | B9: 土 | C9: tǔ | D9: Thổ | E9: đất | F9: trái/dưới | G9: 地、場、城、坐、在、塊、堂
A10: 9 | B10: 金／釒 | C10: jīn | D10: Kim | E10: kim loại; tiền | F10: 釒 bên trái | G10: 錢、銀、鐘、錶、鐵、鍋、鑰
A11: 10 | B11: 日 | C11: rì | D11: Nhật | E11: mặt trời; thời gian | F11: trái/trên | G11: 明、早、晚、時、昨、春、晴
A12: 11 | B12: 月 | C12: yuè | D12: Nguyệt | E12: trăng (nhiều chữ là ⺼ nhục = thịt, cơ thể) | F12: trái | G12: 朋、期、服、腳、臉、胖、腦
A13: 12 | B13: 言／訁 | C13: yán | D13: Ngôn | E13: lời nói | F13: 訁 bên trái | G13: 說、話、語、請、謝、課、讀
... A54: 53 | B54: 攴／攵 | C54: pū | D54: Phộc | E54: đánh nhẹ; hành động | F54: 攵 bên phải | G54: 教、數、放、收、改、政
A55: 54 | B55: 大 | C55: dà | D55: Đại | E55: lớn | G55: 天、太、夫、奇、套
A56: 55 | B56: 小 | C56: xiǎo | D56: Tiểu | E56: nhỏ | G56: 少、尖、尚
A57: 56 | B57: 巾 | C57: jīn | D57: Cân | E57: khăn, vải | G57: 帶、帽、布、希、常
A58: 57 | B58: 网／罒 | C58: wǎng | D58: Võng | E58: lưới | F58: 罒 bên trên | G58: 罵、置、罰、買(罒)
A59: 58 | B59: 隹 | C59: zhuī | D59: Chuy | E59: chim đuôi ngắn | F59: phải | G59: 難、雞、雙、集、雖
A60: 59 | B60: 羊 | C60: yáng | D60: Dương | E60: dê, cừu | G60: 美、群、義、羨
A61: 60 | B61: 老 | C61: lǎo | D61: Lão | E61: già | G61: 考、者

Sheet Chữ ghép đặc biệt
A1: STT | B1: Dạng | C1: Chữ / cấu tạo | D1: Pinyin | E1: Nghĩa | F1: Cách ghi nhớ | G1: Đã thuộc (x)
A2: 1 | B2: Chồng 1→2→3 | C2: 木 → 林 → 森 | D2: mù / lín / sēn | E2: cây → rừng thưa → rừng rậm | F2: Một cây là 木, hai cây thành rừng 林, ba cây thành rừng rậm 森 (森林 = rừng)
A3: 2 | B3: Chồng 1→2→3 | C3: 火 → 炎 → 焱 | D3: huǒ / yán / yàn | E3: lửa → nóng, viêm → ngọn lửa bùng | F3: 炎 dùng trong 發炎 (viêm), 炎熱 (nóng bức)
A4: 3 | B4: Chồng 1→3 | C4: 水 → 淼 | D4: shuǐ / miǎo | E4: nước → mênh mông | F4: 淼 hiếm, dùng trong tên người
A5: 4 | B5: Chồng 1→3 | C5: 口 → 品 | D5: kǒu / pǐn | E5: miệng → phẩm (thưởng thức, sản phẩm) | F5: Nhiều miệng nếm → 品嘗, 產品, 商品
A6: 5 | B6: Chồng 1→2→3 | C6: 日 → 昌 → 晶 | D6: rì / chāng / jīng | E6: mặt trời → hưng thịnh → trong suốt | F6: 晶 trong 水晶 (pha lê)
A7: 6 | B7: Chồng 1→3 | C7: 金 → 鑫 | D7: jīn / xīn | E7: vàng → nhiều tiền của | F7: Hay dùng trong tên cửa hàng
A8: 7 | B8: Chồng 1→3 | C8: 石 → 磊 | D8: shí / lěi | E8: đá → đá chồng chất | F8: 光明磊落 = quang minh lỗi lạc
A9: 8 | B9: Chồng 1→2 | C9: 土 → 圭 | D9: tǔ / guī | E9: đất → ngọc khuê | F9: 圭 là thành phần âm trong 街, 掛, 佳
A10: 9 | B10: Chồng 1→3 | C10: 牛 → 犇 | D10: niú / bēn | E10: trâu → chạy (dạng cổ của 奔)
A11: 10 | B11: Chồng 1→3 | C11: 車 → 轟 | D11: chē / hōng | E11: xe → ầm ầm | F11: Ba chiếc xe chạy → tiếng ầm: 轟炸
A12: 11 | B12: Chồng 1→3 | C12: 耳 → 聶 | D12: ěr / niè | E12: tai → thì thầm (họ Nhiếp) | F12: Phồn thể 聶 có 3 chữ 耳
A13: 12 | B13: Chồng 1→3 | C13: 犬 → 猋 | D13: quǎn / biāo | E13: chó → chó chạy nhanh
A14: 13 | B14: Chồng 1→2 | C14: 夕 → 多 | D14: xī / duō | E14: chiều tối → nhiều | F14: Nhiều buổi chiều chồng lên → nhiều
A15: 14 | B15: Chồng 1→2 | C15: 口 → 呂 | D15: kǒu / lǚ | E15: miệng → họ Lữ | F15: Hai 口 chồng lên (phồn thể 呂, giản thể 吕)
A16: 15 | B16: Hội ý | C16: 人 + 木 = 休 | D16: xiū | E16: nghỉ ngơi | F16: Người tựa vào gốc cây → nghỉ
A17: 16 | B17: Hội ý | C17: 日 + 月 = 明 | D17: míng | E17: sáng | F17: Mặt trời + mặt trăng → sáng
A18: 17 | B18: Hội ý | C18: 女 + 子 = 好 | D18: hǎo | E18: tốt | F18: Có mẹ có con → tốt đẹp
A19: 18 | B19: Hội ý | C19: 田 + 力 = 男 | D19: nán | E19: nam giới | F19: Dùng sức trên ruộng → đàn ông
A20: 19 | B20: Hội ý | C20: 宀 + 女 = 安 | D20: ān | E20: an, yên ổn | F20: Người phụ nữ trong nhà → bình yên
A21: 20 | B21: Hội ý | C21: 手 + 目 = 看 | D21: kàn | E21: nhìn | F21: Đưa tay che trên mắt để nhìn xa
A22: 21 | B22: Hội ý | C22: 人 + 言 = 信 | D22: xìn | E22: tin, thư | F22: Lời người nói ra phải đáng tin
A23: 22 | B23: Hội ý | C23: 小 + 大 = 尖 | D23: jiān | E23: nhọn | F23: Trên nhỏ dưới to → nhọn
A24: 23 | B24: Hội ý | C24: 不 + 正 = 歪 | D24: wāi | E24: lệch, xiêu vẹo | F24: Không ngay → lệch
A25: 24 | B25: Hội ý | C25: 山 + 石 = 岩 | D25: yán | E25: đá núi | F25: Đá trên núi
... A39: 38 | B39: Hình thanh | C39: 門: 們 問 聞 悶 | D39: men / wèn / wén / mèn | E39: (số nhiều) / hỏi / nghe, ngửi / buồn bực | F39: 亻, 口, 耳, 心 + âm 門
A40: 39 | B40: Hình thanh | C40: 分: 份 紛 粉 盼 貧 | D40: fèn / fēn / fěn / pàn / pín | E40: phần / rối / bột / mong / nghèo
A41: 40 | B41: Hình thanh | C41: 里: 理 裡 鯉 厘 | D41: lǐ / lǐ / lǐ / lí | E41: lý / bên trong / cá chép / li | F41: 裡 phồn thể có bộ 衣 (Đài Loan viết 裡 hoặc 裏)
A42: 41 | B42: Hình thanh | C42: 反: 飯 販 板 版 | D42: fàn / fàn / bǎn / bǎn | E42: cơm / buôn bán / tấm ván / bản (in)
A43: 42 | B43: Hình thanh | C43: 非: 排 悲 輩 啡 菲 | D43: pái / bēi / bèi / fēi / fēi | E43: xếp / buồn / thế hệ / (cà phê) / (Philippines)
A44: 43 | B44: Hình thanh | C44: 官: 館 管 棺 | D44: guǎn / guǎn / guān | E44: quán / quản lý / quan tài | F44: 館 phồn thể bộ 食 (giản thể 馆)
A45: 44 | B45: Chữ dễ nhầm | C45: 已 ／ 己 ／ 巳 | D45: yǐ / jǐ / sì | E45: đã / mình / (chi Tỵ) | F45: 已 hở nửa, 己 hở hoàn toàn, 巳 kín
A46: 45 | B46: Chữ dễ nhầm | C46: 未 ／ 末 | D46: wèi / mò | E46: chưa / cuối | F46: 未: nét ngang trên NGẮN; 末: nét ngang trên DÀI
A47: 46 | B47: Chữ dễ nhầm | C47: 買 ／ 賣 | D47: mǎi / mài | E47: mua / bán | F47: Bán (賣) có thêm 士 ở trên — 'có thêm thì mới bán ra'
A48: 47 | B48: Chữ dễ nhầm | C48: 辦 ／ 辨 ／ 辯 ／ 瓣 | D48: bàn / biàn / biàn / bàn | E48: làm / phân biệt / tranh luận / cánh hoa | F48: Giữa là 力 / 丿丶 / 言 / 瓜
A49: 48 | B49: Chữ dễ nhầm | C49: 候 ／ 侯 | D49: hòu / hóu | E49: chờ, lúc (時候) / tước hầu | F49: 候 có một nét sổ nhỏ ở giữa
A50: 49 | B50: Chữ dễ nhầm | C50: 在 ／ 再 | D50: zài / zài | E50: ở, đang / lại, nữa | F50: Cùng âm — 再見, 再說 dùng 再
A51: 50 | B51: Chữ dễ nhầm | C51: 的 ／ 得 ／ 地 | D51: de | E51: trợ từ định ngữ / bổ ngữ / trạng ngữ | F51: adj + 的 + N；V + 得 + bổ ngữ；adv + 地 + V
A52: 51 | B52: Chữ dễ nhầm | C52: 做 ／ 作 | D52: zuò | E52: làm (cụ thể) / tác (trừu tượng) | F52: 做飯, 做事 ／ 工作, 作業, 作文
